<?xml version="1.0" ?>
<!-- =================================================================================== -->
<!-- |    This document was autogenerated by xacro from amr.xacro                      | -->
<!-- |    EDITING THIS FILE BY HAND IS NOT RECOMMENDED                                 | -->
<!-- =================================================================================== -->
<robot name="amr">
  <!-- kp: stiffness coefficient,   [N/m?]  -->
  <!-- kp: stiffness coefficient,   [N/m?]  -->
  <!-- cw_izz: caster wheel inertia z axis, [kgm^2]  -->
  <!-- dwt: driving wheel tread, [m]  -->
  <!-- dw_izz: driving wheel inertia z axis, [kgm^2]  -->
  <!-- ch: chassis center of mass position,  [m] -->
  <!-- c_izz: chassis inertia z axis, [kgm^2]  -->
  <!-- cfwp: caster front wheel position, [m]  -->
  <!--xacro:macro name="driving_wheel_transmission" params="number">
        <transmission name="tran${number}">
            <type>transmission_interface/SimpleTransmission</type>
            <joint name="base_link_driving_wheel_M${number}_joint">
                <hardwareInterface>hardware_interface/VelocityJointInterface</hardwareInterface>
            </joint>
            <actuator name="motor${number}">
                <hardwareInterface>hardware_interface/VelocityJointInterface</hardwareInterface>
                <mechanicalReduction>1</mechanicalReduction>
            </actuator>
        </transmission>
    </xacro:macro-->
  <material name="blue">
    <color rgba="0 0 0.8 1"/>
  </material>
  <material name="red">
    <color rgba="0.8 0 0 1"/>
  </material>
  <material name="green">
    <color rgba="0 0.8 0 1"/>
  </material>
  <material name="grey">
    <color rgba="0.75 0.75 0.75 1"/>
  </material>
  <material name="white">
    <color rgba="1.0 1.0 1.0 1"/>
  </material>
  <material name="black">
    <color rgba="0 0 0 1"/>
  </material>
  <!-- * * * Link Definitions * * * -->
  <link name="base_link">
    <visual>
      <origin rpy="0 0 0" xyz="0 0 0"/>
      <geometry>
        <box size="0.35 0.8 0.05"/>
      </geometry>
      <material name="grey"/>
    </visual>
    <collision>
      <origin rpy="0 0 0" xyz="0 0 0"/>
      <geometry>
        <box size="0.35 0.8 0.05"/>
      </geometry>
    </collision>
    <inertial>
      <origin rpy="0 0 0" xyz="0 0 0"/>
      <!-- default: xyz="0 0 0" rpy="0 0 0" -->
      <mass value="70.0"/>
      <inertia ixx="3.747916666666667" ixy="0.0" ixz="0.0" iyy="0.7291666666666665" iyz="0.0" izz="4.447916666666667"/>
    </inertial>
  </link>
  <gazebo reference="base_link">
    <kp>10000.0</kp>
    <kd>10000.0</kd>
    <mu1>10.0</mu1>
    <mu2>10.0</mu2>
    <material>Gazebo/Grey</material>
  </gazebo>
  <link name="elevator_sx_link">
    <visual>
      <origin rpy="0 0 0" xyz="0 0 0"/>
      <geometry>
        <box size="1.2 0.125 0.05"/>
      </geometry>
      <material name="grey"/>
    </visual>
    <collision>
      <origin rpy="0 0 0" xyz="0 0 0"/>
      <geometry>
        <box size="1.2 0.125 0.05"/>
      </geometry>
    </collision>
    <inertial>
      <origin rpy="0 0 0" xyz="0 0 0"/>
      <!-- default: xyz="0 0 0" rpy="0 0 0" -->
      <mass value="10"/>
      <inertia ixx="3.747916666666667" ixy="0.0" ixz="0.0" iyy="0.7291666666666665" iyz="0.0" izz="4.447916666666667"/>
    </inertial>
  </link>
  <gazebo reference="elevator_sx_link">
    <kp>10000.0</kp>
    <kd>10000.0</kd>
    <mu1>10.0</mu1>
    <mu2>10.0</mu2>
    <material>Gazebo/Grey</material>
  </gazebo>
  <joint name="base_link_elevator_sx_link_joint" type="prismatic">
    <parent link="base_link"/>
    <child link="elevator_sx_link"/>
    <limit effort="1000.0" lower="0" upper="0.080" velocity="0.5"/>
    <origin rpy="0 0 0" xyz="0.85 0.186 0.080"/>
    <axis xyz="0 0 1"/>
  </joint>
  <link name="elevator_dx_link">
    <visual>
      <origin rpy="0 0 0" xyz="0 0 0"/>
      <geometry>
        <box size="1.2 0.125 0.05"/>
      </geometry>
      <material name="grey"/>
    </visual>
    <collision>
      <origin rpy="0 0 0" xyz="0 0 0"/>
      <geometry>
        <box size="1.2 0.125 0.05"/>
      </geometry>
    </collision>
    <inertial>
      <origin rpy="0 0 0" xyz="0 0 0"/>
      <!-- default: xyz="0 0 0" rpy="0 0 0" -->
      <mass value="10"/>
      <inertia ixx="3.747916666666667" ixy="0.0" ixz="0.0" iyy="0.7291666666666665" iyz="0.0" izz="4.447916666666667"/>
    </inertial>
  </link>
  <gazebo reference="elevator_dx_link">
    <kp>10000.0</kp>
    <kd>10000.0</kd>
    <mu1>10.0</mu1>
    <mu2>10.0</mu2>
    <material>Gazebo/Grey</material>
  </gazebo>
  <joint name="base_link_elevator_dx_link_joint" type="prismatic">
    <parent link="base_link"/>
    <child link="elevator_dx_link"/>
    <limit effort="1000.0" lower="0" upper="0.080" velocity="0.5"/>
    <origin rpy="0 0 0" xyz="0.85 -0.186 0.080"/>
    <axis xyz="0 0 1"/>
  </joint>
  <link name="caster_wheel_M1_link">
    <visual>
      <origin rpy="0 0 0" xyz="0 0 0"/>
      <geometry>
        <box size="0.050 0.050 0.0975"/>
      </geometry>
      <material name="green"/>
    </visual>
    <collision>
      <origin rpy="0 0 0" xyz="0 0 0"/>
      <geometry>
        <box size="0.050 0.050 0.0975"/>
      </geometry>
    </collision>
    <inertial>
      <origin rpy="0 0 0" xyz="0 0 0"/>
      <mass value="0.05"/>
      <inertia ixx="0" ixy="0.0" ixz="0.0" iyy="0" iyz="0.0" izz="0"/>
    </inertial>
  </link>
  <gazebo reference="caster_wheel_M1_link">
    <kp>10000.0</kp>
    <kd>10000.0</kd>
    <mu1>10.0</mu1>
    <mu2>10.0</mu2>
    <material>Gazebo/Green</material>
  </gazebo>
  <link name="wheel_M1_link">
    <visual>
      <origin rpy="0 0 0" xyz="0 0 0"/>
      <geometry>
        <cylinder length="0.037" radius="0.0625"/>
      </geometry>
      <material name="red"/>
    </visual>
    <collision>
      <origin rpy="0 0 0" xyz="0 0 0"/>
      <geometry>
        <cylinder length="0.037" radius="0.0625"/>
      </geometry>
    </collision>
    <inertial>
      <origin rpy="0 0 0" xyz="0 0 0"/>
      <mass value="0.5"/>
      <inertia ixx="0.0005453229166666666" ixy="0.0" ixz="0.0" iyy="0.0005453229166666666" iyz="0.0" izz="0.0009765625"/>
    </inertial>
  </link>
  <gazebo reference="wheel_M1_link">
    <kp>5000.0</kp>
    <kd>5000.0</kd>
    <mu1>30.0</mu1>
    <mu2>30.0</mu2>
    <material>Gazebo/Red</material>
  </gazebo>
  <joint name="caster_wheel_M1_wheel_M1_joint" type="continuous">
    <parent link="caster_wheel_M1_link"/>
    <child link="wheel_M1_link"/>
    <origin rpy="1.570796 0 0" xyz="0.047 0 -0.04875"/>
    <limit effort="1.0" velocity="0.005"/>
    <axis xyz="0 0 1"/>
  </joint>
  <link name="caster_wheel_M2_link">
    <visual>
      <origin rpy="0 0 0" xyz="0 0 0"/>
      <geometry>
        <box size="0.050 0.050 0.0975"/>
      </geometry>
      <material name="green"/>
    </visual>
    <collision>
      <origin rpy="0 0 0" xyz="0 0 0"/>
      <geometry>
        <box size="0.050 0.050 0.0975"/>
      </geometry>
    </collision>
    <inertial>
      <origin rpy="0 0 0" xyz="0 0 0"/>
      <mass value="0.05"/>
      <inertia ixx="0" ixy="0.0" ixz="0.0" iyy="0" iyz="0.0" izz="0"/>
    </inertial>
  </link>
  <gazebo reference="caster_wheel_M2_link">
    <kp>10000.0</kp>
    <kd>10000.0</kd>
    <mu1>10.0</mu1>
    <mu2>10.0</mu2>
    <material>Gazebo/Green</material>
  </gazebo>
  <link name="wheel_M2_link">
    <visual>
      <origin rpy="0 0 0" xyz="0 0 0"/>
      <geometry>
        <cylinder length="0.037" radius="0.0625"/>
      </geometry>
      <material name="red"/>
    </visual>
    <collision>
      <origin rpy="0 0 0" xyz="0 0 0"/>
      <geometry>
        <cylinder length="0.037" radius="0.0625"/>
      </geometry>
    </collision>
    <inertial>
      <origin rpy="0 0 0" xyz="0 0 0"/>
      <mass value="0.5"/>
      <inertia ixx="0.0005453229166666666" ixy="0.0" ixz="0.0" iyy="0.0005453229166666666" iyz="0.0" izz="0.0009765625"/>
    </inertial>
  </link>
  <gazebo reference="wheel_M2_link">
    <kp>5000.0</kp>
    <kd>5000.0</kd>
    <mu1>30.0</mu1>
    <mu2>30.0</mu2>
    <material>Gazebo/Red</material>
  </gazebo>
  <joint name="caster_wheel_M2_wheel_M2_joint" type="continuous">
    <parent link="caster_wheel_M2_link"/>
    <child link="wheel_M2_link"/>
    <origin rpy="1.570796 0 0" xyz="0.047 0 -0.04875"/>
    <limit effort="1.0" velocity="0.005"/>
    <axis xyz="0 0 1"/>
  </joint>
  <!-- 
    <xacro:caster_wheel_link number="3" colour="Red"/>
    <xacro:caster_wheel_link number="4" colour="Red"/> -->
  <joint name="base_link_caster_wheel_M1_joint" type="continuous">
    <parent link="base_link"/>
    <child link="caster_wheel_M1_link"/>
    <origin rpy="0 0 0" xyz="1.5 0.186 -0.05"/>
    <!-- xyz="${-clod/2} ${clad/2} ${-ch}" rpy="0 0 0" -->
    <limit effort="1.0" velocity="1"/>
    <axis xyz="0 0 1"/>
  </joint>
  <joint name="base_link_caster_wheel_M2_joint" type="continuous">
    <parent link="base_link"/>
    <child link="caster_wheel_M2_link"/>
    <origin rpy="0 0 0" xyz="1.5 -0.186 -0.05"/>
    <!-- xyz="${-clod/2} ${clad/2} ${-ch}" rpy="0 0 0" -->
    <limit effort="1.0" velocity="1"/>
    <axis xyz="0 0 1"/>
  </joint>
  <!-- 
    <joint name="base_link_caster_wheel_M3_joint" type="continuous">
    	<parent link="base_link"/>
    	<child link="caster_wheel_M3_link"/>
        <origin xyz="${-clod/2} ${clad/2} ${-ch}" rpy="0 0 0"/>
        <limit effort="1.0" velocity="1"/>
        <axis xyz="0 0 1"/>
	</joint>

    <joint name="base_link_caster_wheel_M4_joint" type="continuous">
    	<parent link="base_link"/>
    	<child link="caster_wheel_M4_link"/>
        <origin xyz="${-clod/2} ${-clad/2} ${-ch}" rpy="0 0 0"/> 
        <limit effort="1.0" velocity="1"/>
        <axis xyz="0 0 1"/>
	</joint> -->
  <link name="driving_wheel_M1_link">
    <visual>
      <origin rpy="0 0 0" xyz="0 0 0"/>
      <geometry>
        <cylinder length="0.044" radius="0.0625"/>
      </geometry>
      <material name="blue"/>
    </visual>
    <collision>
      <origin rpy="0 0 0" xyz="0 0 0"/>
      <geometry>
        <cylinder length="0.044" radius="0.0625"/>
      </geometry>
    </collision>
    <inertial>
      <origin rpy="0 0 0" xyz="0 0 0"/>
      <mass value="0.6"/>
      <inertia ixx="0.0006827375" ixy="0.0" ixz="0.0" iyy="0.0006827375" iyz="0.0" izz="0.001171875"/>
    </inertial>
  </link>
  <gazebo reference="driving_wheel_M1_link">
    <kp>25000.0</kp>
    <kd>25000.0</kd>
    <mu1>10.0</mu1>
    <mu2>10.0</mu2>
    <material>Gazebo/Blue</material>
  </gazebo>
  <link name="driving_wheel_M2_link">
    <visual>
      <origin rpy="0 0 0" xyz="0 0 0"/>
      <geometry>
        <cylinder length="0.044" radius="0.0625"/>
      </geometry>
      <material name="blue"/>
    </visual>
    <collision>
      <origin rpy="0 0 0" xyz="0 0 0"/>
      <geometry>
        <cylinder length="0.044" radius="0.0625"/>
      </geometry>
    </collision>
    <inertial>
      <origin rpy="0 0 0" xyz="0 0 0"/>
      <mass value="0.6"/>
      <inertia ixx="0.0006827375" ixy="0.0" ixz="0.0" iyy="0.0006827375" iyz="0.0" izz="0.001171875"/>
    </inertial>
  </link>
  <gazebo reference="driving_wheel_M2_link">
    <kp>25000.0</kp>
    <kd>25000.0</kd>
    <mu1>10.0</mu1>
    <mu2>10.0</mu2>
    <material>Gazebo/Blue</material>
  </gazebo>
  <joint name="base_link_driving_wheel_M1_joint" type="continuous">
    <parent link="base_link"/>
    <child link="driving_wheel_M1_link"/>
    <origin rpy="1.57 0 0" xyz="0 -0.4 -0.0975"/>
    <limit effort="15.0" velocity="0.1"/>
    <axis xyz="0 0 -1"/>
  </joint>
  <joint name="base_link_driving_wheel_M2_joint" type="continuous">
    <parent link="base_link"/>
    <child link="driving_wheel_M2_link"/>
    <origin rpy="1.57 0 0" xyz="0 0.4 -0.0975"/>
    <limit effort="15.0" velocity="0.1"/>
    <axis xyz="0 0 -1"/>
  </joint>
  <gazebo>
    <plugin filename="libgazebo_ros_diff_drive.so" name="differential_drive_controller">
      <alwaysOn>true</alwaysOn>
      <updateRate>50</updateRate>
      <leftJoint>base_link_driving_wheel_M2_joint</leftJoint>
      <rightJoint>base_link_driving_wheel_M1_joint</rightJoint>
      <wheelSeparation>0.8440000000000001</wheelSeparation>
      <wheelDiameter>0.125</wheelDiameter>
      <wheelAcceleration>0.2</wheelAcceleration>
      <wheelTorque>30</wheelTorque>
      <commandTopic>cmd_vel</commandTopic>
      <odometryTopic>odom</odometryTopic>
      <odometryFrame>odom</odometryFrame>
      <robotBaseFrame>base_footprint</robotBaseFrame>
      <publishWheelTF>true</publishWheelTF>
      <publishOdom>true</publishOdom>
      <robotBaseFrame>base_link</robotBaseFrame>
      <publishWheelJointState>true</publishWheelJointState>
      <legacyMode>false</legacyMode>
      <rosDebugLevel>false</rosDebugLevel>
      <publishOdomTF>true</publishOdomTF>
      <odometrySource>1</odometrySource>
      <publishTf>1</publishTf>
    </plugin>
  </gazebo>
  <!--xacro:driving_wheel_transmission number="1"/>
    <xacro:driving_wheel_transmission number="2"/-->
  <!-- ############# Sensors ############ -->
  <!-- Depth sensor in the front -->
  <link name="front_dcamera_link">
    <visual>
      <origin rpy="0.0 0 0" xyz="0 0 0"/>
      <geometry>
        <box size="0.0005 0.0005 0.0005"/>
      </geometry>
      <material name="green"/>
    </visual>
  </link>
  <joint name="base_front_dcamera_joint" type="fixed">
    <parent link="base_link"/>
    <child link="front_dcamera_link"/>
    <origin rpy="0 0 0" xyz="0.175 0 0"/>
  </joint>
  <gazebo reference="front_dcamera_link">
    <sensor name="front_depth_camera" type="depth">
      <update_rate>20</update_rate>
      <camera>
        <horizontal_fov>1.047198</horizontal_fov>
        <image>
          <width>640</width>
          <height>480</height>
          <format>R8G8B8</format>
        </image>
        <clip>
          <near>0.05</near>
          <far>3</far>
        </clip>
      </camera>
      <plugin filename="libgazebo_ros_openni_kinect.so" name="front_depth_link_controller">
        <baseline>0.2</baseline>
        <alwaysOn>true</alwaysOn>
        <updateRate>1.0</updateRate>
        <cameraName>front_dcamera</cameraName>
        <imageTopicName>front_dcamera/color/image_raw</imageTopicName>
        <cameraInfoTopicName>/front_dcamera/color/camera_info</cameraInfoTopicName>
        <depthImageTopicName>/front_dcamera/depth/image_raw</depthImageTopicName>
        <depthImageInfoTopicName>/front_dcamera/depth/camera_info</depthImageInfoTopicName>
        <pointCloudTopicName>/front_dcamera/depth/points</pointCloudTopicName>
        <frameName>front_dcamera_link</frameName>
        <pointCloudCutoff>0.5</pointCloudCutoff>
        <pointCloudCutoffMax>3.0</pointCloudCutoffMax>
        <distortionK1>0.00000001</distortionK1>
        <distortionK2>0.00000001</distortionK2>
        <distortionK3>0.00000001</distortionK3>
        <distortionT1>0.00000001</distortionT1>
        <distortionT2>0.00000001</distortionT2>
        <CxPrime>0</CxPrime>
        <Cx>0</Cx>
        <Cy>0</Cy>
        <focalLength>0</focalLength>
        <hackBaseline>0</hackBaseline>
      </plugin>
    </sensor>
  </gazebo>
  <!-- Depth sensor in the back -->
  <link name="rear_dcamera_link">
    <visual>
      <origin rpy="0.0 0 0" xyz="0 0 0"/>
      <geometry>
        <box size="0.0005 0.0005 0.0005"/>
      </geometry>
      <material name="green"/>
    </visual>
  </link>
  <joint name="base_rear_dcamera_joint" type="fixed">
    <parent link="base_link"/>
    <child link="rear_dcamera_link"/>
    <origin rpy="0 0 3.1416" xyz="-0.175 0 0"/>
  </joint>
  <gazebo reference="rear_dcamera_link">
    <sensor name="rear_depth_camera" type="depth">
      <update_rate>20</update_rate>
      <camera>
        <horizontal_fov>1.047198</horizontal_fov>
        <image>
          <width>640</width>
          <height>480</height>
          <format>R8G8B8</format>
        </image>
        <clip>
          <near>0.05</near>
          <far>3</far>
        </clip>
      </camera>
      <plugin filename="libgazebo_ros_openni_kinect.so" name="rear_depth_link_controller">
        <baseline>0.2</baseline>
        <alwaysOn>true</alwaysOn>
        <updateRate>1.0</updateRate>
        <cameraName>rear_dcamera</cameraName>
        <imageTopicName>rear_dcamera/color/image_raw</imageTopicName>
        <cameraInfoTopicName>/rear_dcamera/color/camera_info</cameraInfoTopicName>
        <depthImageTopicName>/rear_dcamera/depth/image_raw</depthImageTopicName>
        <depthImageInfoTopicName>/rear_dcamera/depth/camera_info</depthImageInfoTopicName>
        <pointCloudTopicName>/rear_dcamera/depth/points</pointCloudTopicName>
        <frameName>rear_dcamera_link</frameName>
        <pointCloudCutoff>0.5</pointCloudCutoff>
        <pointCloudCutoffMax>3.0</pointCloudCutoffMax>
        <distortionK1>0.00000001</distortionK1>
        <distortionK2>0.00000001</distortionK2>
        <distortionK3>0.00000001</distortionK3>
        <distortionT1>0.00000001</distortionT1>
        <distortionT2>0.00000001</distortionT2>
        <CxPrime>0</CxPrime>
        <Cx>0</Cx>
        <Cy>0</Cy>
        <focalLength>0</focalLength>
        <hackBaseline>0</hackBaseline>
      </plugin>
    </sensor>
  </gazebo>
  <!-- Sensor Laser in the front -->
  <link name="front_laserscanner_link">
    <visual>
      <origin rpy="0.0 0 0" xyz="0 0 0"/>
      <geometry>
        <box size="0.005 0.005 0.005"/>
      </geometry>
      <material name="green"/>
    </visual>
    <collision>
      <origin rpy="0.0 0 0" xyz="0 0 0"/>
      <geometry>
        <box size="0.005 0.005 0.005"/>
      </geometry>
    </collision>
    <inertial>
      <mass value="1e-5"/>
      <origin rpy="0 0 0" xyz="0 0 0"/>
      <inertia ixx="1e-6" ixy="0" ixz="0" iyy="1e-6" iyz="0" izz="1e-6"/>
    </inertial>
  </link>
  <joint name="base_front_laserscanner_joint" type="fixed">
    <axis xyz="0 1 0"/>
    <parent link="base_link"/>
    <child link="front_laserscanner_link"/>
    <origin rpy="0 0 0" xyz="0.175 0.4 0"/>
  </joint>
  <gazebo reference="front_laserscanner_link">
    <sensor name="front_rplidar_sensor" type="ray">
      <pose>0 0 0 0 0 0</pose>
      <visualize>false</visualize>
      <update_rate>40</update_rate>
      <ray>
        <scan>
          <horizontal>
            <samples>720</samples>
            <resolution>1</resolution>
            <min_angle>-1.4</min_angle>
            <max_angle>3.1416</max_angle>
          </horizontal>
        </scan>
        <range>
          <min>0.10</min>
          <max>30.0</max>
          <resolution>0.01</resolution>
        </range>
        <noise>
          <type>gaussian</type>
          <!-- Noise parameters based on published spec for Hokuyo laser
                         achieving "+-30mm" accuracy at range < 10m.  A mean of 0.0m and
                         stddev of 0.01m will put 99.7% of samples within 0.03m of the true
                         reading. -->
          <mean>0.0</mean>
          <stddev>0.01</stddev>
        </noise>
      </ray>
      <plugin filename="libgazebo_ros_laser.so" name="gazebo_ros_head_hokuyo_controller">
        <topicName>front_scan</topicName>
        <frameName>front_laserscanner_link</frameName>
      </plugin>
    </sensor>
  </gazebo>
  <!--gazebo reference="rplidar_link">
        <material>Gazebo/FlatBlack</material>
    </gazebo-->
  <!-- Sensor Laser in the back -->
  <link name="rear_laserscanner_link">
    <visual>
      <origin rpy="0.0 0 0" xyz="0 0 0"/>
      <geometry>
        <box size="0.0005 0.0005 0.0005"/>
      </geometry>
      <material name="green"/>
    </visual>
    <collision>
      <origin rpy="0.0 0 0" xyz="0 0 0"/>
      <geometry>
        <box size="0.0005 0.0005 0.0005"/>
      </geometry>
    </collision>
    <inertial>
      <mass value="1e-5"/>
      <origin rpy="0 0 0" xyz="0 0 0"/>
      <inertia ixx="1e-6" ixy="0" ixz="0" iyy="1e-6" iyz="0" izz="1e-6"/>
    </inertial>
  </link>
  <joint name="base_rear_laserscanner_joint" type="fixed">
    <parent link="base_link"/>
    <child link="rear_laserscanner_link"/>
    <origin rpy="0 0 3.14159268" xyz="-0.175 -0.4 0"/>
  </joint>
  <gazebo reference="rear_laserscanner_link">
    <sensor name="rear_rplidar_sensor" type="ray">
      <pose>0 0 0 0 0 0</pose>
      <visualize>false</visualize>
      <update_rate>40</update_rate>
      <ray>
        <scan>
          <horizontal>
            <samples>720</samples>
            <resolution>1</resolution>
            <min_angle>-1.4</min_angle>
            <max_angle>3.1416</max_angle>
          </horizontal>
        </scan>
        <range>
          <min>0.10</min>
          <max>30.0</max>
          <resolution>0.01</resolution>
        </range>
        <noise>
          <type>gaussian</type>
          <!-- Noise parameters based on published spec for Hokuyo laser
                         achieving "+-30mm" accuracy at range < 10m.  A mean of 0.0m and
                         stddev of 0.01m will put 99.7% of samples within 0.03m of the true
                         reading. -->
          <mean>0.0</mean>
          <stddev>0.01</stddev>
        </noise>
      </ray>
      <plugin filename="libgazebo_ros_laser.so" name="gazebo_ros_head_hokuyo_controller">
        <topicName>rear_scan</topicName>
        <frameName>rear_laserscanner_link</frameName>
      </plugin>
    </sensor>
  </gazebo>
</robot>

